<?xml version="1.0" ?>
<!-- =================================================================================== -->
<!-- |    This document was autogenerated by xacro from ddrive.xacro                   | -->
<!-- |    EDITING THIS FILE BY HAND IS NOT RECOMMENDED                                 | -->
<!-- =================================================================================== -->
<robot name="diff_drive">
  <gazebo reference="base_link">
    <material>Gazebo/Green</material>
  </gazebo>
  <gazebo reference="wheel_left">
    <mu1>5000</mu1>
    <mu2>5000</mu2>
    <material>Gazebo/Black</material>
  </gazebo>
  <gazebo reference="wheel_right">
    <mu1>5000</mu1>
    <mu2>5000</mu2>
    <material>Gazebo/Black</material>
  </gazebo>
  <gazebo refrence="t_castor">
    <mu1>0</mu1>
    <mu2>0</mu2>
    <material>Gazebo/Blue</material>
  </gazebo>
  <gazebo reference="b_castor">
    <mu1>0</mu1>
    <mu2>0</mu2>
    <material>Gazebo/Red</material>
  </gazebo>
  <!-- Gazebo Plugin -->
  <gazebo>
    <plugin filename="libgazebo_ros_diff_drive.so" name="differential_drive_controller">
      <rosDebugLevel>na</rosDebugLevel>
      <alwaysOn>true</alwaysOn>
      <updateRate>100</updateRate>
      <leftJoint>l_wheel</leftJoint>
      <rightJoint>r_wheel</rightJoint>
      <wheelSeparation>0.12000000000000001</wheelSeparation>
      <wheelDiameter>0.16</wheelDiameter>
      <wheelTorque>20</wheelTorque>
      <commandTopic>dd/cmd_vel</commandTopic>
      <odometryTopic>dd/odom</odometryTopic>
      <odometryFrame>dd/odom</odometryFrame>
      <robotBaseFrame>base_link</robotBaseFrame>
      <publishWheelTF>false</publishWheelTF>
      <publishOdomTF>true</publishOdomTF>
      <publishWheelJointState>true</publishWheelJointState>
      <wheelAcceleration>false</wheelAcceleration>
      <odometrySource>world</odometrySource>
      <publishTf>1</publishTf>
    </plugin>
  </gazebo>
  <!-- A differential drive robot -->
  <!-- Body Details -->
  <link name="base_footprint"/>
  <joint name="base_joint" type="fixed">
    <!-- the fixed joint, fixing base footprint to robot body -->
    <parent link="base_footprint"/>
    <child link="base_link"/>
    <origin rpy="0 0 0" xyz="0 0 0"/>
  </joint>
  <link name="base_link">
    <!-- the cuboid -->
    <visual>
      <origin rpy="0 0 0" xyz="0 0 0.07200000000000001"/>
      <geometry>
        <box size="0.1 0.2 0.05"/>
      </geometry>
      <material name="green">
        <color rgba="0 1 0 1"/>
      </material>
    </visual>
    <collision>
      <origin rpy="0 0 0" xyz="0 0 0.08"/>
      <geometry>
        <box size="0.1 0.2 0.05"/>
      </geometry>
    </collision>
    <inertial>
      <origin rpy="0 0 0" xyz="0 0 0.08"/>
      <mass value="0.97"/>
      <inertia ixx="0.0034354166666666678" ixy="0.0" ixz="0.0" iyy="0.0010104166666666668" iyz="0.0" izz="0.004041666666666667"/>
    </inertial>
  </link>
  <!-- Wheel Details -->
  <joint name="l_wheel" type="continuous">
    <!-- the left wheel joint -->
    <parent link="base_link"/>
    <child link="wheel_left"/>
    <origin rpy="0 1.5707963267948966 0" xyz="-0.060000000000000005 -0.08 0.08"/>
    <axis xyz="0 0 1"/>
  </joint>
  <joint name="r_wheel" type="continuous">
    <!-- the right wheel joint -->
    <parent link="base_link"/>
    <child link="wheel_right"/>
    <origin rpy="0 1.5707963267948966 0" xyz="0.060000000000000005 -0.08 0.08"/>
    <axis xyz="0 0 1"/>
  </joint>
  <link name="wheel_left">
    <!-- the left wheel link -->
    <visual>
      <origin rpy="0 0 0" xyz="0 0 0"/>
      <geometry>
        <cylinder length="0.02" radius="0.08"/>
      </geometry>
      <material name="black">
        <color rgba="0 0 0 1"/>
      </material>
    </visual>
    <collision>
      <origin rpy="0 0 0" xyz="0 0 0"/>
      <geometry>
        <cylinder length="0.02" radius="0.08"/>
      </geometry>
    </collision>
    <inertial>
      <origin rpy="0 0 0" xyz="0 0 0"/>
      <mass value="0.2"/>
      <inertia ixx="0.00064" ixy="0" ixz="0" iyy="0.0003266666666666667" iyz="0" izz="0.0003266666666666667"/>
    </inertial>
  </link>
  <link name="wheel_right">
    <!-- the right wheel link -->
    <visual>
      <origin rpy="0 0 0" xyz="0 0 0"/>
      <geometry>
        <cylinder length="0.02" radius="0.08"/>
      </geometry>
      <material name="black">
        <color rgba="0 0 0 0"/>
      </material>
    </visual>
    <collision>
      <origin rpy="0 0 0" xyz="0 0 0"/>
      <geometry>
        <cylinder length="0.02" radius="0.08"/>
      </geometry>
    </collision>
    <inertial>
      <oorigin rpy="0 0 0" xyz="0 0 0"/>
      <mass value="0.2"/>
      <inertia ixx="0.00064" ixy="0" ixz="0" iyy="0.0003266666666666667" iyz="0" izz="0.0003266666666666667"/>
    </inertial>
  </link>
  <!-- Castor Details -->
  <joint name="castor_top" type="continuous">
    <!-- the top castor joint -->
    <parent link="base_link"/>
    <child link="t_castor"/>
    <origin rpy="0 0 0" xyz="0 0.07 0.1325"/>
  </joint>
  <joint name="castor_bottom" type="continuous">
    <!-- the bottom castor joint -->
    <parent link="base_link"/>
    <child link="b_castor"/>
    <origin rpy="0 0 0" xyz="0 0.07 0.0275"/>
  </joint>
  <link name="t_castor">
    <!-- the top castor link -->
    <visual>
      <origin rpy="0 0 0" xyz="0 0 0"/>
      <geometry>
        <sphere radius="0.0275"/>
      </geometry>
      <material name="blue">
        <color rgba="0 0 1 1"/>
      </material>
    </visual>
    <collision>
      <origin rpy="0 0 0" xyz="0 0 0"/>
      <geometry>
        <sphere radius="0.0275"/>
      </geometry>
    </collision>
    <inertial>
      <origin rpy="0 0 0" xyz="0 0 0"/>
      <mass value="0.05"/>
      <inertia ixx="1.5125000000000002e-05" ixy="0" ixz="0" iyy="1.5125000000000002e-05" iyz="0" izz="1.5125000000000002e-05"/>
    </inertial>
  </link>
  <link name="b_castor">
    <!-- the bottom link -->
    <visual>
      <origin rpy="0 0 0" xyz="0 0 0"/>
      <geometry>
        <sphere radius="0.0275"/>
      </geometry>
      <material name="orange"/>
      <material name="blue">
        <color rgba="0.5 0 0.5 1"/>
      </material>
    </visual>
    <collision>
      <origin rpy="0 0 0" xyz="0 0 0"/>
      <geometry>
        <sphere radius="0.0275"/>
      </geometry>
    </collision>
    <inertial>
      <origin rpy="0 0 0" xyz="0 0 0"/>
      <mass value="0.05"/>
      <inertia ixx="1.5125000000000002e-05" ixy="0" ixz="0" iyy="1.5125000000000002e-05" iyz="0" izz="1.5125000000000002e-05"/>
    </inertial>
  </link>
</robot>

