<?xml version="1.0"?>
    <robot xmlns:xacro="http://www.ros.org/wiki/xacro" name="robotarm">

<!-- Load in parameters from the YAML file -->
<xacro:property name="props" value="${load_yaml('$(find homework2)/config/arm.yaml')}"/>

<!-- Set parameters -->
<xacro:property name="L1" value="${props['L1']}" />
<xacro:property name="L2" value="${props['L2']}" />
<xacro:property name="r" value="0.1"/>

<!-- A planar robot with 2 revolute joints -->

<!-- The base for arm 1 to rotate about -->
<link name="base_link">
    <visual>
        <geometry>
            <sphere radius="0.1" />
        </geometry>
        <material name="green_metal">
            <color rgba="0 1 0 0" />
        </material>
    </visual>
</link>

<!-- The first link/ arm of the two arm robot -->
<link name="arm1">
    <visual>
    <origin xyz="0.5 0 0" rpy="0 1.57 0" />
    <geometry>
        <cylinder radius="0.1" length="1.0" />
    </geometry>
    <material name="blue_metal">
        <color rgba="0 0 1 1" />
    </material>
    </visual>
</link>

<!-- The second link/ arm of the robot -->
<link name="arm2">
    <visual>
    <origin xyz="1 0 0" rpy="0 1.57 0" />
        <geometry>
            <cylinder radius="0.1" length="2.0" />
        </geometry>
        <material name="red_mat">
           <color rgba="1 0 0 1" />
        </material>
    </visual>
</link>

<!-- The invisible link at end effector to create a frame -->
<link name="end_frame">
    <visual>
    <origin xyz="0 0 0" rpy="0 0 0" />
        <geometry>
            <sphere radius="0.1" />
        </geometry>
        <material name="green_metal">
            <color rgba="0 1 0 0" />
        </material>
    </visual>
</link>

<!-- Revolute joint between base and arm1 -->
<joint name="rev1" type="continuous">
    <origin xyz="0 0 0" rpy="0 0 0" />
    <parent link="base_link" />
    <child link="arm1" />
    <axis xyz="0 0 1" />
</joint>

<!-- Joint between arm1 and arm2 -->
<joint name="rev2" type="continuous">
    <origin xyz="1 0 0" rpy="0 0 0" />
    <parent link="arm1" />
    <child link="arm2" />
    <axis xyz="0 0 1" />
</joint>

<!-- To fix the end effector to end of arm2 -->
<joint name="end" type="fixed">
    <origin xyz="2 0 0" rpy="0 0 0" />
    <parent link="arm2" />
    <child link="end_frame" />
</joint>

</robot>


